Workbook

Sheet Stakeholder notes
A1: note_id | B1: stakeholder_name | C1: stakeholder_role | D1: quote_or_observation | E1: Assigned Theme
A2: SN-001 | B2: Amina Rahman | C2: Compliance Liaison | D2: Customers respond well when they have control and transparency about what they owe. | E2: Customer friction
A3: SN-002 | B3: Daniel Okoye | C3: Finance Business Partner | D3: Customers call back three times because they do not remember what they were told on the first call. | E3: Customer friction
A4: SN-003 | B4: Priya Nair | C4: Operations Manager | D4: Simple cases that could be resolved in minutes take days because they get stuck in the wrong queue. | E4: Delayed or missed follow-up
A5: SN-004 | B5: Gareth Evans | C5: Senior Collections Team Leader | D5: Leadership approved the roadmap five years ago and never came back to debt recovery. | E5: Change resistance or distrust
A6: SN-005 | B6: Tracy Field | C6: Systems Administrator | D6: Some customers will do anything if given the chance to manage this themselves. | E6: Customer friction
A7: SN-006 | B7: Sylvia Turner | C7: Operations Analyst | D7: We have no way to tell whether a customer is genuinely unable to pay or simply avoiding contact. | E7: Poor account-status visibility
A8: SN-007 | B8: Lawrence Bennett | C8: Finance Analyst | D8: We have cases sitting in 'awaiting callback' status for months because the promised date was never recorded. | E8: Delayed or missed follow-up
A9: SN-008 | B9: Andrea Hunt | C9: Operations Manager | D9: The audit trail is scattered across email, spreadsheets, and the legacy database, making compliance reviews a nightmare. | E9: Poor account-status visibility
A10: SN-009 | B10: Kimberley Richards-Stokes | C10: Service Design Lead | D10: Some customers will never use a portal no matter how good it is, and we need to plan for that. | E10: Customer friction
A11: SN-010 | B11: Mr Philip Stone | C11: Service Design Lead | D11: A single customer can have five separate records in the system from different entry points. | E11: Duplicated work
A12: SN-011 | B12: Christopher Richards | C12: Collections Representative | D12: The collections database does not sync with the email tracker, so representatives often re-contact customers who were already promised callbacks. | E12: Duplicated work
... A15: SN-014 | B15: Stewart Howell | C15: Operations Analyst | D15: We cannot tell whether a case failed because of process breakdown or deliberate non-compliance. | E15: Poor account-status visibility
A16: SN-015 | C16: Compliance Liaison | D16: A case marked 'resolved' in one system might be 'in progress' in another. | E16: Poor account-status visibility
A17: SN-016 | B17: Mr Dale Jackson | C17: Collections Representative | D17: The old system was designed for half the volume we handle now, and it shows. | E17: Change resistance or distrust
A18: SN-017 | B18: Eleanor Clark | C18: Service Design Lead | D18: Most customers do not even know they can pay online; they think they have to call. | E18: Customer friction
A19: SN-018 | B19: Daniel Farmer | C19: Finance Analyst | D19: Some representatives have been doing this for so long they are faster than the system, and they will resist change. | E19: Change resistance or distrust
A20: SN-019 | B20: Mr Martyn Akhtar | C20: Operations Analyst | D20: I cannot recommend automating anything until I see that it will not create new compliance risks. | E20: Change resistance or distrust
A21: SN-020 | B21: Ronald Rees | C21: Collections Representative | D21: New representatives take two weeks longer to reach productivity because they have to learn the spreadsheet system. | E21: Duplicated work
A22: SN-021 | B22: Clare Willis | C22: Service Design Lead | D22: With over 100,000 accounts, we cannot manage this manually any longer, yet that is exactly what we are doing. | E22: Change resistance or distrust
A23: SN-022 | B23: Rebecca Davis | C23: Compliance Liaison | D23: The database was designed for a tenth of the volume we handle now, and performance degrades as we approach month-end. | E23: Change resistance or distrust
A24: SN-023 | B24: Dr Louis Sinclair | C24: Service Design Lead | D24: We have more accounts in the system than our representatives can possibly contact in a reasonable timeframe. | E24: Delayed or missed follow-up
A25: SN-024 | B25: Dr Laura Roberts | C25: Compliance Liaison | D25: The scale of the problem means that even small improvements in efficiency multiply significantly. | E25: Change resistance or distrust
A26: SN-025 | B26: Dr Lynda Smith | C26: Operations Analyst | D26: The spreadsheet is now two hundred sheets thick and no one knows what half of them do. | E26: Duplicated work
A27: SN-026 | B27: Katherine Taylor-Evans | C27: Finance Analyst | D27: We have never measured how often a case comes back because we have no way to track it. | E27: Poor account-status visibility
A28: SN-027 | B28: Karl Lewis-Warren | C28: Operations Analyst | D28: Representatives spend time proving what they did rather than doing more work. | E28: Duplicated work
... A33: SN-032 | B33: Daniel Farmer | C33: Finance Analyst | D33: We lose customers because the recovery process is so slow they lose faith we will ever resolve it. | E33: Delayed or missed follow-up
A34: SN-033 | C34: Compliance Liaison | D34: We could recover an extra 5% of balances if we just contacted people at the right time. | E34: Delayed or missed follow-up
A35: SN-034 | B35: Lawrence Bennett | C35: Collections Representative | D35: Representatives are ready for better tools; they are tired of workarounds. | E35: Change resistance or distrust
A36: SN-035 | C36: Systems Administrator | D36: The database cannot handle the complexity of modern lending products and customer situations. | E36: Change resistance or distrust
A37: SN-036 | B37: Robert Quinn | C37: Process Improvement Lead | D37: Customers get transferred between departments and have to repeat their entire situation each time. | E37: Customer friction
A38: SN-037 | B38: Gareth Evans | C38: Operations Analyst | D38: The first contact with a customer is often not optimised because we do not know their full history. | E38: Poor account-status visibility
A39: SN-038 | B39: Sylvia Turner | C39: Operations Analyst | D39: The biggest win will be when representatives stop checking whether work was already done. | E39: Duplicated work
A40: SN-039 | B40: Simon Burns | C40: Compliance Liaison | D40: We do not have a way to identify which cases are straightforward versus which require specialist handling. | E40: Poor account-status visibility
A41: SN-040 | B41: Catherine Frost | C41: Data Analyst | D41: We lose at least 20% of follow-ups because they fall between shifts and no one owns the handoff. | E41: Delayed or missed follow-up
A42: SN-041 | B42: Peter Chambers | C42: Customer Service Lead | D42: We cannot automate the decision about whether a customer is genuinely in hardship or just dodging contact. | E42: Change resistance or distrust
A43: SN-042 | B43: Jennifer Hayes | C43: Systems Administrator | D43: We cannot tell whether a case failed because the representative made a mistake or because the customer is genuinely unable to pay. | E43: Poor account-status visibility
A44: SN-043 | B44: Simon Burns | C44: Compliance Liaison | D44: We need to measure whether this is better before we commit to rolling it out. | E44: Change resistance or distrust
A45: SN-044 | B45: Robert Quinn | C45: Process Improvement Lead | D45: If a customer pays even a small amount, the whole case gets reclassified and we lose months of history. | E45: Poor account-status visibility
A46: SN-045 | B46: Amina Rahman | C46: Head of Debt Recovery Operations | D46: The contact strategy is reactive—we contact people only when collections escalates them. | E46: Delayed or missed follow-up
...

Sheet Delinquent accounts
A1: account_id | B1: customer_id | C1: customer_name | D1: product_type | E1: delinquency_stage | F1: days_past_due | G1: overdue_amount | H1: total_balance | I1: risk_flag | J1: current_status | K1: email | L1: mobile_phone | M1: postcode | N1: last_contact_channel | O1: self_service_candidate | P1: created_date
A2: ACC-10001 | B2: CUST-50001 | C2: Naomi Clarke | D2: credit_card | E2: early | F2: 28 | G2: 1747.22 | H2: 14822.54 | I2: N | J2: plan_requested | K2: samuel11@example.net | L2: 42570632673 | M2: DD6H 8ZY | N2: letter | O2: Y | P2: 45993
A3: ACC-10002 | B3: CUST-50002 | C3: Dr Cameron Osborne | D3: personal_loan | E3: late | F3: 71 | G3: 772.39 | H3: 11496.59 | I3: Y | J3: Awaiting Follow Up | K3: kathleenmann@example.net | L3: 25813515656 | M3: W3 3NH | N3: email | O3: N | P3: 46000
A4: ACC-10003 | B4: CUST-50003 | C4: Heather Chapman | D4: credit_card | E4: early | F4: 26 | G4: 448.04 | H4: 14187.91 | I4: N | J4: plan_requested | K4: kathleenmorton@example.net | L4: 13900506764 | M4: CW15 2GJ | N4: phone | O4: Y | P4: 45987
A5: ACC-10004 | B5: CUST-50004 | C5: Rachael Butler-Bryant | D5: credit_card | E5: mid | F5: 37 | G5: 582.96 | H5: 14010.54 | I5: N | J5: email_sent | L5: 45463827169 | M5: B5D 7FE | N5: phone | O5: Y | P5: 45936
A6: ACC-10005 | B6: CUST-50005 | C6: William Bryant-Webb | D6: credit_card | E6: mid | F6: 45 | G6: 1300.23 | H6: 8733 | I6: N | J6: legal_watch | K6: gerald93@example.org | L6: 52289753626 | M6: L3 8ZB | N6: email | O6: Y | P6: 45965
A7: ACC-10006 | B7: CUST-50006 | C7: Robin Morris | D7: auto_finance | E7: mid | F7: 35 | G7: 362.91 | H7: 1788.57 | I7: N | J7: new_delinquency | K7: saramason@example.com | L7: 81202044445 | M7: TF8Y 4WY | N7: letter | O7: Y | P7: 46007
A8: ACC-10007 | B8: CUST-50007 | C8: Dr Reece Rose | D8: personal_loan | E8: early | F8: 5 | G8: 597.43 | H8: 14015.12 | I8: N | J8: promise_due | K8: reedshannon@example.net | L8: 61726202463 | M8: G0E 2BQ | N8: sms | O8: Y | P8: 46020
A9: ACC-10008 | B9: CUST-50008 | C9: Dorothy Bell | D9: credit_card | E9: early | F9: 23 | G9: 661.54 | H9: 10639.95 | I9: N | J9: manual_follow_up | K9: longpaul@example.com | L9: 99176632489 | M9: BD0A 0LF | O9: Y | P9: 45936
A10: ACC-10009 | B10: CUST-50009 | C10: Dr Connor Thomas | D10: personal_loan | E10: early | F10: 7 | G10: 1503.9 | H10: 12681.76 | I10: N | J10: email_sent | K10: sinclairanne@example.com | M10: KY4P 3UH | N10: sms | O10: Y | P10: 46029
A11: ACC-10010 | B11: CUST-50010 | C11: Mr Alex Taylor | D11: credit_card | E11: early | F11: 15 | G11: 1228.13 | H11: 9184.91 | I11: N | J11: no_response_cycle | K11: alanperkins@example.org | L11: 2164226547 | M11: CO9N 5YB | O11: Y | P11: 46042
A12: ACC-10011 | B12: CUST-50011 | C12: Dr Kathleen Ward | D12: personal_loan | E12: mid | F12: 56 | G12: 386.4 | H12: 12257.55 | I12: N | J12: awaiting_follow_up | K12: jonescarolyn@example.com | L12: 96527796128 | M12: B1 8YZ | O12: Y | P12: 45951
A13: ACC-10012 | B13: CUST-50012 | C13: Donald Donnelly | D13: credit_card | E13: early | F13: 11 | G13: 682.65 | H13: 13621.16 | I13: N | J13: plan_requested | K13: gerardrowe@example.net | L13: 51084777687 | M13: CB0P 1DP | N13: sms | O13: Y | P13: 46006
A14: ACC-10013 | B14: CUST-50013 | C14: Mrs Shannon James | D14: credit_card | E14: mid | F14: 45 | G14: 729.81 | H14: 6839.45 | I14: N | J14: new_delinquency | K14: pcoates@example.org | L14: 88228671202 | M14: S1H 5SZ | N14: phone | O14: Y | P14: 45935
A15: ACC-10014 | B15: CUST-50014 | C15: Brett Singh | D15: personal_loan | E15: early | F15: 13 | G15: 1566.5 | H15: 7156.99 | I15: Y | J15: promise_due | K15: danielsrosemary@example.com | L15: 88404142953 | M15: W0D 4YQ | N15: phone | O15: N | P15: 46018
A16: ACC-10015 | B16: CUST-50015 | C16: Mr Bernard Smith | D16: credit_card | E16: late | F16: 62 | G16: 1501.59 | H16: 15228.98 | I16: Y | J16: specialist_review | K16: jlewis@example.net | L16: 32750935905 | M16: G6D 3FW | N16: letter | O16: N | P16: 46040
A17: ACC-10016 | B17: CUST-50016 | C17: Sarah Hall | D17: credit_card | E17: late | F17: 113 | G17: 1558.83 | H17: 2446.02 | I17: N | J17: email sent | K17: conor42@example.com | L17: 35249640795 | M17: E0H 8RB | N17: email | O17: N | P17: 46022
A18: ACC-10017 | B18: CUST-50017 | C18: Eric Barry | D18: credit_card | E18: early | F18: 13 | G18: 128.42 | H18: 5556.24 | I18: N | J18: plan_requested | K18: brian76@example.net | L18: 28973634006 | M18: CF49 3TP | N18: phone | O18: Y | P18: 45973
A19: ACC-10018 | B19: CUST-50018 | C19: Ben Lane | D19: credit_card | E19: early | F19: 7 | G19: 1301.41 | H19: 3982.73 | I19: N | J19: specialist_review | K19: kellygeraldine@example.net | L19: 33226247040 | M19: DH3 8PE | O19: Y | P19: 45985
A20: ACC-10019 | B20: CUST-50019 | C20: Emma Wyatt | D20: personal_loan | E20: early | F20: 28 | G20: 896.1 | H20: 9198.91 | I20: N | J20: new_delinquency | K20: ehughes@example.com | L20: 56020223311 | M20: G3T 4FX | N20: email | O20: Y | P20: 45967
A21: ACC-10020 | B21: CUST-50020 | C21: Mrs Karen Brennan | D21: credit_card | E21: mid | F21: 58 | G21: 642.15 | H21: 10061.96 | I21: N | J21: new_delinquency | K21: nknight@example.org | L21: 91684370335 | M21: IM31 8GQ | O21: Y | P21: 45988
A22: ACC-10021 | B22: CUST-50021 | C22: Mark Wood-Smith | D22: personal_loan | E22: early | F22: 8 | G22: 900.88 | H22: 10538.77 | I22: Y | J22: specialist_review | K22: damian46@example.com | L22: 40391581782 | M22: TF44 3QF | N22: email | O22: N | P22: 46001
A23: ACC-10022 | B23: CUST-50022 | C23: Mr Jay Ferguson | D23: personal_loan | E23: early | F23: 17 | G23: 1275.07 | H23: 3231.5 | I23: Y | J23: plan_requested | K23: barbararowley@example.org | L23: 82324755216 | M23: SE4M 4UQ | N23: sms | O23: N | P23: 45986
A24: ACC-10023 | B24: CUST-50023 | C24: Mrs Beverley Riley | D24: personal_loan | E24: mid | F24: 32 | G24: 1681.9 | H24: 8188.01 | I24: N | J24: email_sent | K24: kdavies@example.org | L24: 36702855659 | M24: B1T 2TJ | N24: sms | O24: Y | P24: 45953
A25: ACC-10024 | B25: CUST-50024 | C25: Marilyn Glover-Mills | D25: personal_loan | E25: early | F25: 27 | G25: 1212.68 | H25: 9017.01 | I25: Y | J25: new_delinquency | K25: isaunders@example.org | L25: 75176280069 | M25: N11 3NJ | N25: sms | O25: N | P25: 46039
A26: ACC-10025 | B26: CUST-50025 | C26: Adam Morris-Lewis | D26: credit_card | E26: mid | F26: 39 | G26: 453.28 | H26: 13320.62 | I26: N | J26: awaiting_follow_up | L26: 495219135 | M26: KY8 3BL | N26: letter | O26: Y | P26: 45981
A27: ACC-10026 | B27: CUST-50026 | C27: Yvonne Preston | D27: personal_loan | E27: mid | F27: 37 | G27: 1302.31 | H27: 3558.24 | I27: N | J27: legal_watch | K27: omorgan@example.org | L27: 72100319569 | M27: LD5 4RB | N27: email | O27: Y | P27: 46013
A28: ACC-10027 | B28: CUST-50027 | C28: Nathan Bird | D28: credit_card | E28: late | F28: 102 | G28: 1700.93 | H28: 10074.31 | I28: Y | K28: kevinwilliams@example.net | L28: 87505332565 | M28: M90 4QU | O28: N | P28: 46036
A29: ACC-10028 | B29: CUST-50028 | C29: Eric Fowler | D29: credit_card | E29: late | F29: 88 | G29: 981.66 | H29: 10743.17 | I29: Y | J29: specialist_review | K29: jonesemma@example.com | L29: 67568602498 | M29: JE82 2ZX | N29: email | O29: N | P29: 45981
A30: ACC-10029 | B30: CUST-50029 | C30: Hannah Metcalfe | D30: credit_card | E30: early | F30: 17 | G30: 729.89 | H30: 14193.89 | I30: N | J30: plan_requested | K30: abdul90@example.net | L30: 81647237630 | M30: B5 1BW | N30: phone | O30: Y | P30: 45958
A31: ACC-10030 | B31: CUST-50030 | C31: Anna Mason-West | D31: personal_loan | E31: late | F31: 87 | G31: 406.56 | H31: 14114.63 | I31: Y | J31: specialist_review | M31: DH12 7LP | N31: email | O31: N | P31: 45975
A32: ACC-10031 | B32: CUST-50031 | C32: Naomi Smith | D32: credit_card | E32: early | F32: 27 | G32: 650.63 | H32: 9941.88 | I32: N | J32: manual_follow_up | K32: juliapugh@example.org | L32: 24286143109 | M32: S9 4GW | N32: letter | O32: Y | P32: 45932
A33: ACC-10032 | B33: CUST-50032 | C33: Susan Hamilton | D33: personal_loan | E33: early | F33: 9 | G33: 1788.68 | H33: 12003.84 | I33: N | J33: promise_due | K33: jbailey@example.org | L33: 67681241773 | M33: S96 0ZX | N33: sms | O33: Y | P33: 46021
A34: ACC-10033 | B34: CUST-50033 | C34: Geoffrey Jones-Hughes | D34: credit_card | E34: early | F34: 6 | G34: 1568.75 | H34: 8767.18 | I34: N | J34: awaiting_follow_up | K34: marc98@example.com | L34: 37439812559 | M34: CT0 8XX | N34: email | O34: Y | P34: 46031
A35: ACC-10034 | B35: CUST-50034 | C35: Brian Gibson-Graham | D35: personal_loan | E35: mid | F35: 37 | G35: 643.34 | H35: 1776.37 | I35: N | J35: specialist_review | K35: ellie60@example.net | L35: 6955851059 | M35: CA0 2JZ | N35: sms | O35: Y | P35: 46043
A36: ACC-10035 | B36: CUST-50035 | C36: Kerry Smith | D36: personal_loan | E36: mid | F36: 40 | G36: 485.46 | H36: 10324.18 | I36: N | J36: specialist_review | L36: 68828841543 | M36: G3 0UA | N36: phone | O36: Y | P36: 45978
A37: ACC-10036 | B37: CUST-50036 | C37: Dr Stephen Ward | D37: auto_finance | E37: early | F37: 22 | G37: 1685.69 | H37: 12357.23 | I37: N | J37: new_delinquency | K37: joshua29@example.net | L37: 91473267182 | M37: B9 1SJ | N37: phone | O37: Y | P37: 46021
A38: ACC-10037 | B38: CUST-50037 | C38: Elliot Miah | D38: credit_card | E38: mid | F38: 43 | G38: 365.08 | H38: 4012.64 | I38: N | J38: manual_follow_up | K38: kelly50@example.com | L38: 16115256537 | M38: N27 7TQ | N38: phone | O38: Y | P38: 45979
A39: ACC-10038 | B39: CUST-50038 | C39: Julie Norris | D39: personal_loan | E39: mid | F39: 51 | G39: 541.82 | H39: 1330.69 | I39: N | J39: new_delinquency | K39: nwallace@example.net | L39: 95243079840 | M39: S01 4YF | N39: phone | O39: Y | P39: 46003
A40: ACC-10039 | B40: CUST-50039 | C40: Patricia Cartwright-Phillips | D40: personal_loan | E40: early | F40: 17 | G40: 1288.67 | H40: 2152.48 | I40: N | J40: plan_requested | K40: owenkathryn@example.org | L40: 60214936268 | M40: B0W 4TH | O40: Y | P40: 46025
...

Sheet Recovery activity tracker
A1: activity_id | B1: account_id | C1: activity_date | D1: activity_type | E1: performed_by | F1: source_system | G1: outcome_code | H1: next_follow_up_date | I1: minutes_spent | J1: duplicate_check_flag
A2: ACT-00001 | B2: ACC-10001 | C2: 46056 | D2: status_check | E2: representative_38 | F2: spreadsheet | G2: next_action_unclear | I2: 3 | J2: N
A3: ACT-00002 | B3: ACC-10001 | C3: 46041 | D3: manual_plan_note | E3: representative_48 | F3: phone | G3: viewed_status | H3: 46046 | I3: 8 | J3: N
A4: ACT-00003 | B4: ACC-10001 | C4: 46049 | D4: status_check | E4: representative_32 | F4: phone | G4: promise_to_pay | H4: 46056 | I4: 4 | J4: Y
A5: ACT-00004 | B5: ACC-10001 | C5: 46061 | D5: email_sent | E5: representative_08 | F5: phone | G5: no_reply | H5: 46066 | I5: 4 | J5: N
A6: ACT-00005 | B6: ACC-10001 | C6: 46059 | D6: escalation | E6: representative_28 | F6: spreadsheet | G6: next_action_unclear | I6: 8 | J6: N
A7: ACT-00006 | B7: ACC-10002 | C7: 46027 | D7: call_attempt | E7: representative_05 | F7: phone | G7: promise_to_pay | H7: 46028 | I7: 11 | J7: N
A8: ACT-00007 | B8: ACC-10002 | C8: 46034 | D8: spreadsheet_reconcile | E8: representative_04 | F8: legacy_db | G8: next_action_unclear | H8: 46034 | I8: 9 | J8: Y
A9: ACT-00008 | B9: ACC-10002 | C9: 46039 | D9: email_sent | E9: representative_25 | F9: phone | G9: awaiting_review | H9: 46045 | I9: 5 | J9: N
A10: ACT-00009 | B10: ACC-10002 | C10: 46025 | D10: escalation | E10: representative_04 | F10: legacy_db | G10: updated_row | H10: 46025 | I10: 6 | J10: N
A11: ACT-00010 | B11: ACC-10002 | C11: 46028 | D11: manual_plan_note | E11: representative_49 | F11: phone | G11: awaiting_review | H11: 46031 | I11: 10 | J11: N
A12: ACT-00011 | B12: ACC-10003 | C12: 46068 | D12: manual_plan_note | E12: representative_09 | F12: phone | G12: left_message | I12: 10 | J12: N
A13: ACT-00012 | B13: ACC-10003 | C13: 46066 | D13: email_sent | E13: representative_48 | F13: legacy_db | G13: no_reply | H13: 46072 | I13: 4 | J13: N
A14: ACT-00013 | B14: ACC-10003 | C14: 46062 | D14: spreadsheet_reconcile | E14: representative_49 | F14: email | G14: sent_to_specialist | H14: 46063 | I14: 12 | J14: N
A15: ACT-00014 | B15: ACC-10003 | C15: 46061 | D15: status_check | E15: representative_06 | F15: spreadsheet | G15: next_action_unclear | H15: 46063 | I15: 5 | J15: Y
A16: ACT-00015 | B16: ACC-10003 | C16: 46076 | D16: status_check | E16: representative_48 | F16: email | G16: awaiting_review | H16: 46083 | I16: 3 | J16: Y
A17: ACT-00016 | B17: ACC-10004 | C17: 46066 | D17: spreadsheet_reconcile | E17: representative_36 | F17: phone | G17: updated_row | H17: 46072 | I17: 10 | J17: N
A18: ACT-00017 | B18: ACC-10004 | C18: 46068 | D18: call_attempt | E18: representative_33 | F18: spreadsheet | G18: sent_to_specialist | H18: 46068 | I18: 11 | J18: N
A19: ACT-00018 | B19: ACC-10005 | C19: 46049 | D19: email_sent | E19: representative_49 | F19: phone | G19: updated_row | I19: 4 | J19: N
A20: ACT-00019 | B20: ACC-10006 | C20: 46052 | D20: call_attempt | E20: representative_30 | F20: phone | G20: no_reply | I20: 12 | J20: N
A21: ACT-00020 | B21: ACC-10007 | C21: 46044 | D21: call_attempt | E21: representative_27 | F21: legacy_db | G21: next_action_unclear | H21: 46049 | I21: 11 | J21: N
A22: ACT-00021 | B22: ACC-10007 | C22: 46046 | D22: status_check | E22: representative_07 | F22: phone | G22: left_message | H22: 46048 | I22: 4 | J22: Y
A23: ACT-00022 | B23: ACC-10007 | C23: 46046 | D23: call_attempt | E23: representative_35 | F23: phone | G23: sent_to_specialist | H23: 46051 | I23: 9 | J23: N
A24: ACT-00023 | B24: ACC-10008 | C24: 46066 | D24: email_sent | E24: representative_35 | F24: phone | G24: awaiting_review | H24: 46066 | I24: 7 | J24: N
A25: ACT-00024 | B25: ACC-10008 | C25: 46054 | D25: manual_plan_note | E25: representative_07 | F25: legacy_db | G25: updated_row | H25: 46056 | I25: 5 | J25: N
A26: ACT-00025 | B26: ACC-10009 | C26: 46062 | D26: spreadsheet_reconcile | E26: representative_34 | F26: email | G26: updated_row | H26: 46066 | I26: 9 | J26: Y
A27: ACT-00026 | B27: ACC-10009 | C27: 46058 | D27: call_attempt | E27: representative_22 | F27: legacy_db | G27: no_reply | H27: 46064 | I27: 14 | J27: N
A28: ACT-00027 | B28: ACC-10009 | C28: 46076 | D28: sms_reminder | E28: representative_09 | F28: spreadsheet | G28: left_message | H28: 46079 | I28: 4 | J28: N
A29: ACT-00028 | B29: ACC-10010 | C29: 46051 | D29: escalation | E29: representative_01 | F29: phone | G29: sent_to_specialist | H29: 46052 | I29: 11 | J29: N
A30: ACT-00029 | B30: ACC-10010 | C30: 46039 | D30: spreadsheet_reconcile | E30: representative_40 | F30: legacy_db | G30: updated_row | H30: 46039 | I30: 10 | J30: Y
A31: ACT-00030 | B31: ACC-10010 | C31: 46046 | D31: call_attempt | E31: representative_51 | F31: spreadsheet | G31: awaiting_review | H31: 46048 | I31: 14 | J31: N
A32: ACT-00031 | B32: ACC-10010 | C32: 46047 | D32: sms_reminder | E32: representative_53 | F32: spreadsheet | G32: next_action_unclear | I32: 3 | J32: N
A33: ACT-00032 | B33: ACC-10010 | C33: 46054 | D33: email_sent | E33: representative_48 | F33: legacy_db | G33: updated_row | H33: 46056 | I33: 4 | J33: N
A34: ACT-00033 | B34: ACC-10011 | C34: 46081 | D34: escalation | E34: representative_16 | F34: spreadsheet | G34: awaiting_review | H34: 46086 | I34: 10 | J34: N
A35: ACT-00034 | B35: ACC-10011 | C35: 46064 | D35: spreadsheet_reconcile | E35: representative_43 | F35: phone | G35: left_message | H35: 46067 | I35: 9 | J35: N
A36: ACT-00035 | B36: ACC-10011 | C36: 46068 | D36: call_attempt | E36: representative_43 | F36: legacy_db | G36: viewed_status | H36: 46068 | I36: 13 | J36: N
A37: ACT-00036 | B37: ACC-10012 | C37: 46074 | D37: email_sent | E37: representative_34 | F37: legacy_db | G37: sent_to_specialist | H37: 46076 | I37: 5 | J37: N
A38: ACT-00037 | B38: ACC-10012 | C38: 46072 | D38: call_attempt | E38: representative_28 | F38: spreadsheet | G38: next_action_unclear | H38: 46077 | I38: 11 | J38: N
A39: ACT-00038 | B39: ACC-10012 | C39: 46071 | D39: email_sent | E39: representative_42 | F39: spreadsheet | G39: viewed_status | H39: 46071 | I39: 5 | J39: N
A40: ACT-00039 | B40: ACC-10012 | C40: 46075 | D40: sms_reminder | E40: representative_24 | F40: legacy_db | G40: updated_row | H40: 46079 | I40: 4 | J40: N
...

Sheet Stakeholder Evidence
A1: Stakeholder | B1: Quote or Observation | C1: Theme | D1: Business Impact | E1: Confidence Level
A2: Amina Rahman (Compliance Liaison) | B2: Customers respond well when they have control and transparency about what they owe. | C2: Customer friction | D2: Transparent balance presentation increases voluntary settlements and lowers inbound support call volume. | E2: High
A3: Daniel Okoye (Finance Business Partner) | B3: Customers call back three times because they do not remember what they were told on the first call. | C3: Customer friction | D3: Repeat inbound calls inflate handling costs and extend the average resolution cycle time. | E3: High
A4: Tracy Field (Systems Administrator) | B4: Some customers will do anything if given the chance to manage this themselves. | C4: Customer friction | D4: Lack of digital self-service tools forces willing payers into high-cost manual agent channels. | E4: High
A5: Kimberley Richards-Stokes (Service Design Lead) | B5: Some customers will never use a portal no matter how good it is, and we need to plan for that. | C5: Customer friction | D5: Channel strategy must preserve assisted support options for digitally excluded or resistant customers. | E5: High
A6: Eleanor Clark (Service Design Lead) | B6: Most customers do not even know they can pay online; they think they have to call. | C6: Customer friction | D6: Low digital channel awareness drives unnecessary telephone queues and inflates operational expenses. | E6: High
A7: Robert Quinn (Process Improvement Lead) | B7: Customers get transferred between departments and have to repeat their entire situation each time. | C7: Customer friction | D7: Inter-departmental handoffs frustrate customers, lowering satisfaction and escalating complaint risk. | E7: High
A8: Diana White (Collections Representative) | B8: We are exposed to complaint risk because customers cannot track what we have told them. | C8: Customer friction | D8: Absence of customer-visible confirmation logs invites payment disputes and ombudsman escalations. | E8: High
A9: Dr Lynda Smith (Operations Analyst) | B9: Customers would pay more readily if they understood exactly what they owe and could see options. | C9: Customer friction | D9: Providing transparent balance breakdowns and flexible installment options accelerates payment velocity. | E9: High
A10: Tracy Field (Compliance Liaison) | B10: If the portal works, it will work because it gives customers control, not because it is fancier. | C10: Customer friction | D10: Customer empowerment and autonomy serve as the primary behavioral drivers for digital debt resolution. | E10: High
A11: Tracy Field (Compliance Liaison) | B11: The portal could work brilliantly for the 40% of customers who want to resolve this themselves. | C11: Customer friction | D11: Diverting 40% of routine cases to self-service unlocks major frontline capacity for complex arrears. | E11: High
A12: Thomas Wright (Operations Manager) | B12: If the portal works, it will work because it gives customers control, not because it is fancier. | C12: Customer friction | D12: Focusing on user autonomy over aesthetic complexity ensures higher self-service adoption. | E12: High
... A127: James Morrison (Quality Assurance Lead) | B127: Our representatives are creative and adaptable; they will find ways to use the portal effectively. | C127: Change resistance or distrust | D127: Staff adaptability offers a strong foundation for successful digital change management. | E127: Medium

Sheet JTBD Analysis
A1: JTBD ID | B1: Actor | C1: Statement | D1: Evidence Link | E1: Portal Relevance | F1: Frequency of Evidence | G1: Business Impact Rank | H1: Portal Relevance Rank | I1: Overall Priority
A2: JTBD-01 | B2: Customer | C2: When I need to resolve an outstanding balance, I want to see exactly what I owe and the options available, so I can choose a manageable way to pay. | D2: Dr Lynda Smith (Operations Analyst): "Customers would pay more readily if they understood exactly what they owe and could see options." | E2: Shows clear balance details and enables customers to set up manageable payment plans directly online. | F2: High | G2: High | H2: High | I2: High
A3: JTBD-02 | B3: Customer | C3: When my case moves between departments, I want my history and previous conversations to follow me, so I do not have to explain my situation again. | D3: Robert Quinn (Process Improvement Lead): "Customers get transferred between departments and have to repeat their entire situation each time." | E3: Maintains a shared history across departments so customers never have to repeat their situation when transferred. | F3: Medium | G3: High | H3: High | I3: High
A4: JTBD-03 | B4: Collections representative | C4: When I pick up a case, I want to see recent contacts and promised callbacks in one reliable place, so I can follow through without duplicating outreach. | D4: Christopher Richards (Collections Representative): "The collections database does not sync with the email tracker, so representatives often re-contact customers who were already promised callbacks." | E4: Syncs customer online actions and payment promises into staff records to prevent duplicate outreach. | F4: Medium | G4: High | H4: Medium | I4: Medium
A5: JTBD-04 | B5: Operations manager | C5: When new cases enter the workflow, I want them routed according to their needs and complexity, so straightforward cases are not delayed behind cases requiring specialist handling. | D5: Priya Nair (Operations Manager): "Simple cases that could be resolved in minutes take days because they get stuck in the wrong queue." | E5: Handles routine payments online, freeing staff queues to focus on complex cases needing specialist help. | F5: High | G5: High | H5: High | I5: High
A6: JTBD-05 | B6: Customer | C6: When I need an update on my account, I want to see a clear record of past conversations, actions, and next steps, so I can check my progress without calling for information I have already been given. | D6: Diana White: "We are exposed to complaint risk because customers cannot track what we have told them." & Daniel Okoye | E6: Provides an account dashboard with payment history and agreed plans so customers can check progress without calling. | F6: High | G6: High | H6: High | I6: High
A7: JTBD-06 | B7: Finance analyst | C7: When forecasting recovery revenue, I want timely, reliable activity data, so I can produce forecasts with confidence. | D7: Daniel Farmer (Finance Analyst): "The finance team cannot forecast recovery revenue because they do not trust the activity data." | E7: Captures accurate transaction and payment records to provide reliable data for financial forecasting. | F7: Low | G7: High | H7: Low | I7: Medium
A8: JTBD-07 | B8: Operations manager | C8: When reviewing a case, I want its audit trail available in one place, so I can demonstrate what happened without reconciling scattered records. | D8: Andrea Hunt (Operations Manager): "The audit trail is scattered across email, spreadsheets, and the legacy database, making compliance reviews a nightmare." | E8: Creates a single, clear record of all account actions and agreements for straightforward compliance audits. | F8: High | G8: High | H8: Medium | I8: High
A9: JTBD-08 | B9: Customer | C9: When I believe my balance is incorrect, I want a clear way to raise and track a dispute, so I can get the issue reviewed before being asked to pay. | D9: Simon Burns (Compliance Liaison): "The portal would be great, but what happens when someone disputes the balance?" | E9: Allows customers to submit disputes, upload documents, and pause collections while issues are reviewed. | F9: Medium | G9: High | H9: High | I9: High
A10: JTBD-09 | B10: Collections representative | C10: When I promise a customer a callback, I want the due date recorded and surfaced to the right person, so the customer is not left waiting and the case keeps moving. | D10: Dr Louis Sinclair (Service Design Lead): "Cases get stuck in 'pending callback' status indefinitely because the callback date is never enforced." | E10: Lets customers book callback times that sync directly to staff schedules to ensure timely follow-ups. | F10: High | G10: High | H10: Medium | I10: Medium
A11: JTBD-10 | B11: Customer service representative | C11: When a customer may be experiencing hardship or vulnerability, I want to assess their circumstances with appropriate discretion, so they receive support that fits their situation rather than an unsuitable automated decision. | D11: Peter Chambers (Customer Service Lead): "We cannot automate the decision about whether a customer is genuinely in hardship or just dodging contact." | E11: Spots signs of financial hardship or vulnerability and immediately routes customers to specialist support. | F11: High | G11: High | H11: High | I11: High
E20: Job | F20: Strategic Role | G20: Why It’s in the Top 3
E21: **JTBD-01** *(Balance & Plan)* | F21: **The Front Door** | G21: Gives the 40% of straightforward customers total transparency and the ability to self-serve immediately.
E22: **JTBD-04** *(Smart Triage)* | F22: **The Operational Core** | G22: Unblocks staff queues by separating simple routine arrears from complex debt.
E23: **JTBD-10** *(Vulnerability Off-Ramp)* | F23: **The Safety Shield** | G23: Ensures regulatory compliance and protects vulnerable debtors by routing them straight to human specialists.

Sheet Task Breakdown
A1: Task Name | B1: Task Count | C1: Total Minutes | D1: Average Minutes | E1: Calculation & Origin
A2: call_attempt | B2: =COUNTIF('Recovery activity tracker'!$D$2:$D$9891, A2) -> 1397 | C2: =SUMIF('Recovery activity tracker'!$D$2:$D$9891, A2, 'Recovery activity tracker'!$I$2:$I$9891) -> 15312 | D2: =IFERROR(C2/B2, 0) -> 10.96063 | E2: Aggregated from Recovery activity tracker: Task Count = COUNTIF(activity_type,"call_attempt"); Total Mins = SUMIF(activity_type,"call_attempt",minutes_spent); Avg = 15,312 / 1,397 = 11.0 mins.
A3: email_sent | B3: =COUNTIF('Recovery activity tracker'!$D$2:$D$9891, A3) -> 1382 | C3: =SUMIF('Recovery activity tracker'!$D$2:$D$9891, A3, 'Recovery activity tracker'!$I$2:$I$9891) -> 7580 | D3: =IFERROR(C3/B3, 0) -> 5.4848046 | E3: Aggregated from Recovery activity tracker: Task Count = COUNTIF(activity_type,"email_sent"); Total Mins = SUMIF(activity_type,"email_sent",minutes_spent); Avg = 7,580 / 1,382 = 5.5 mins.
A4: escalation | B4: =COUNTIF('Recovery activity tracker'!$D$2:$D$9891, A4) -> 1423 | C4: =SUMIF('Recovery activity tracker'!$D$2:$D$9891, A4, 'Recovery activity tracker'!$I$2:$I$9891) -> 12025 | D4: =IFERROR(C4/B4, 0) -> 8.4504568 | E4: Aggregated from Recovery activity tracker: Task Count = COUNTIF(activity_type,"escalation"); Total Mins = SUMIF(activity_type,"escalation",minutes_spent); Avg = 12,025 / 1,423 = 8.5 mins.
A5: manual_plan_note | B5: =COUNTIF('Recovery activity tracker'!$D$2:$D$9891, A5) -> 1405 | C5: =SUMIF('Recovery activity tracker'!$D$2:$D$9891, A5, 'Recovery activity tracker'!$I$2:$I$9891) -> 10554 | D5: =IFERROR(C5/B5, 0) -> 7.5117438 | E5: Aggregated from Recovery activity tracker: Task Count = COUNTIF(activity_type,"manual_plan_note"); Total Mins = SUMIF(activity_type,"manual_plan_note",minutes_spent); Avg = 10,554 / 1,405 = 7.5 mins.
A6: sms_reminder | B6: =COUNTIF('Recovery activity tracker'!$D$2:$D$9891, A6) -> 1425 | C6: =SUMIF('Recovery activity tracker'!$D$2:$D$9891, A6, 'Recovery activity tracker'!$I$2:$I$9891) -> 4285 | D6: =IFERROR(C6/B6, 0) -> 3.0070175 | E6: Aggregated from Recovery activity tracker: Task Count = COUNTIF(activity_type,"sms_reminder"); Total Mins = SUMIF(activity_type,"sms_reminder",minutes_spent); Avg = 4,285 / 1,425 = 3.0 mins.
A7: spreadsheet_reconcile | B7: =COUNTIF('Recovery activity tracker'!$D$2:$D$9891, A7) -> 1458 | C7: =SUMIF('Recovery activity tracker'!$D$2:$D$9891, A7, 'Recovery activity tracker'!$I$2:$I$9891) -> 13123 | D7: =IFERROR(C7/B7, 0) -> 9.0006859 | E7: Aggregated from Recovery activity tracker: Task Count = COUNTIF(activity_type,"spreadsheet_reconcile"); Total Mins = SUMIF(activity_type,"spreadsheet_reconcile",minutes_spent); Avg = 13,123 / 1,458 = 9.0 mins. Baseline source for B-03 and OP-06.
A8: status_check | B8: =COUNTIF('Recovery activity tracker'!$D$2:$D$9891, A8) -> 1400 | C8: =SUMIF('Recovery activity tracker'!$D$2:$D$9891, A8, 'Recovery activity tracker'!$I$2:$I$9891) -> 6347 | D8: =IFERROR(C8/B8, 0) -> 4.5335714 | E8: Aggregated from Recovery activity tracker: Task Count = COUNTIF(activity_type,"status_check"); Total Mins = SUMIF(activity_type,"status_check",minutes_spent); Avg = 6,347 / 1,400 = 4.5 mins. Sourced as balance inquiry baseline for assumption FA-24 and opportunity OP-01 (404 annualized hours saved).
A9: Total / Portfolio Average | B9: =SUM(B2:B8) -> 9890 | C9: =SUM(C2:C8) -> 69226 | D9: =IFERROR(C9/B9, 0) -> 6.9995956 | E9: Portfolio total across all logged recovery records: Count = SUM(B2:B8) (9,890 tasks); Total Mins = SUM(C2:C8) (69,226 mins); Portfolio Weighted Average = 69,226 / 9,890 = 7.0 mins (Assumption FA-16).

Sheet Assumptions
A1: assumption_id | B1: assumption_name | C1: value | D1: unit | E1: source | F1: confidence_level | G1: notes | H1: Calculation & Origin
A2: FA-01 | B2: representative_hourly_cost | C2: 22 | D2: GBP | E2: Finance workbook | F2: High | G2: Blended representative hourly cost | H2: Sourced from Finance workbook and HR payroll models; represents the standard fully loaded representative wage (£22/hr) including employment taxes and facility overhead.
A3: FA-02 | B3: working_days_per_month | C3: 21 | D3: days | E3: Finance workbook | F3: High | G3: Used for admin calculations | H3: Sourced from Finance operational calendar; calculated as standard 252 annual working days divided by 12 months = 21 average working days per month.
A4: FA-03 | B4: straightforward_case_share | C4: 0.38 | D4: ratio | E4: Operations estimate | F4: Medium | G4: Suitable for rules-driven self-service | H4: Sourced from Operations leadership estimate and stakeholder interviews (SN-082, SN-099); represents the estimated 38% proportion of delinquent cases eligible for automated/self-service deflection.
A5: FA-04 | B5: avg_straightforward_case_minutes | C5: 18 | D5: minutes | E5: Operations leadership | F5: Medium | G5: Current case handling time | H5: Sourced from Operations leadership time-and-motion study; represents the current baseline handling duration (18 mins) for manual representative handling of routine arrears inquiries.
A6: FA-05 | B6: target_straightforward_case_minutes | C6: 10 | D6: minutes | E6: Operations target | F6: Medium | G6: Target after automation support | H6: Target set by Operations leadership; assumes digital self-service balance viewing and automated routing reduce representative handling time by 8 minutes down to 10 minutes per case.
A7: FA-06 | B7: missed_follow_up_rate | C7: 0.14 | D7: ratio | E7: Activity tracker analysis | F7: Medium | G7: Indicative rate of missed or delayed follow-up | H7: Derived from Recovery activity tracker log analysis (~14.8% unassigned follow-up dates) and operational benchmarks; reflects estimated rate of missed or delayed follow-ups.
A8: FA-07 | B8: recovery_uplift_for_plan_selection | C8: 0.04 | D8: ratio | E8: Finance estimate | F8: Low | G8: Test in sensitivity analysis | H8: Modeled in Finance sensitivity analysis; represents an estimated 4.0% recovery rate uplift on delinquent balances when debtors select structured self-serve payment plans.
A9: FA-08 | B9: recovery_uplift_for_promise_capture | C9: 0.025 | D9: ratio | E9: Finance estimate | F9: Low | G9: Scenario based | H9: Modeled in Finance scenario analysis; represents an estimated 2.5% recovery rate uplift achieved via immediate digital capture and automated confirmation of promises to pay.
A10: FA-09 | B10: monthly_recovery_baseline | C10: 8000000 | D10: GBP | E10: Finance workbook | F10: Medium | G10: Baseline monthly recoveries | H10: Sourced directly from Finance monthly management accounts; reflects baseline gross collections of £8.0M per month (£96M annualized) across delinquent debt operations.
A11: FA-10 | B11: implementation_cost_low_complexity | C11: 45000 | D11: GBP | E11: Product delivery estimate | F11: Medium | G11: Starter figure | H11: Sourced from Product delivery engineering estimates; standard capex cost (£45,000) for low-complexity portal modules (e.g., balance views, reminder dispatch).
A12: FA-11 | B12: implementation_cost_medium_complexity | C12: 85000 | D12: GBP | E12: Product delivery estimate | F12: Medium | G12: Starter figure | H12: Sourced from Product delivery engineering estimates; standard capex cost (£85,000) for medium-complexity integrations (e.g., plan selection engines, routing logic).
A13: FA-12 | B13: total_delinquent_balance | C13: 26559358 | D13: GBP | E13: Delinquent accounts | F13: High | G13: Total portfolio delinquent balance (£3.05M overdue; £940 avg overdue) | H13: Calculated as =SUM(DelinquentAccounts[total_balance]) across all 3,246 customer records in Delinquent accounts tab (£26,559,358.36 total delinquent balance).
... A24: FA-23 | B24: revenue_straightforward_case_share | C24: 0.38 | D24: ratio | E24: Operations estimate | F24: Medium | G24: Straightforward case share applied to revenue calculations | H24: Sourced from FA-03 (38% straightforward case share); applied as eligible case proportion to model revenue uplifts for digital promise capture (OP-03) and payment-plan selection (OP-04).
A25: FA-24 | B25: balance_inquiry_annual_hours_saved | C25: =IFERROR(__xludf.DUMMYFUNCTION("ROUND('Task Breakdown'!C8/60/COUNTUNIQUE('Recovery activity tracker'!$C$2:$C$9891)*$C$3*12, 0)"),404.0) -> 404 | D25: hours | E25: Recovery activity tracker & Task Breakdown | F25: High | G25: Annual representative hours spent on routine balance inquiries (status checks) | H25: Derived from Recovery activity tracker status_check volume (1,400 activities, 6,347 mins across 66 tracking days; Task Breakdown row 8). Annualized as: 6,347 mins / 60 / 66 days * 21 days/mo (FA-02) * 12 mos = 404 annual hours saved for OP-01, replacing prior straightforward case assumption.

Sheet Baseline metrics
A1: metric_id | B1: metric_name | C1: current_value | D1: unit | E1: source | F1: confidence_level | G1: notes | H1: Calculation & Origin
A2: B-01 | B2: total_delinquent_account_volume | C2: =COUNTA('Delinquent accounts'!A2:A3247) -> 3246 | D2: accounts | E2: Delinquent accounts extract | F2: High | G2: Total active delinquent accounts identified from the delinquent accounts extract (ACC-10001 to ACC-13246) | H2: Calculated as =COUNTA(DelinquentAccounts[account_id]) across the Delinquent accounts tab (ACC-10001 through ACC-13246), totaling 3,246 unique active delinquent accounts.
A3: B-02 | B3: likely_straightforward_case_volume | C3: =ROUND(C2*Assumptions!C4, 0) -> 1233 | D3: cases/month | E3: Delinquent accounts & Assumptions (FA-03) | F3: Medium | G3: Estimated monthly straightforward cases based on 38% straightforward case share (FA-03) applied to delinquent accounts | H3: Calculated as =ROUND(B-01 * FA-03) (3,246 delinquent accounts * 38% straightforward case share = 1,233 monthly cases eligible for self-service deflection).
A4: B-03 | B4: admin_hours_spent_on_manual_work | C4: =IFERROR(__xludf.DUMMYFUNCTION("ROUND(SUMIF('Recovery activity tracker'!D:D, ""spreadsheet_reconcile"", 'Recovery activity tracker'!I:I) / 60 / COUNTUNIQUE('Recovery activity tracker'!C2:C9891), 2)"),3.31) -> 3.31 | D4: hours/day | E4: Recovery activity tracker & Assumptions (FA-02) | F4: Medium | G4: Daily representative hours lost to spreadsheet reconciliation (~218.7 hrs total across 66 tracking days) | H4: Calculated from Recovery activity tracker: 13,123 total minutes spent on 'spreadsheet_reconcile' (218.72 hours) divided across 66 tracking days = 3.31 representative hours per working day.
A5: B-04 | B5: missed_follow_up_rate | C5: =Assumptions!C7 -> 0.14 | D5: ratio | E5: Activity tracker analysis (FA-06) | F5: Medium | G5: Indicative baseline rate of missed or delayed follow-ups (FA-06; 14.8% unassigned follow-up dates in activity tracker) | H5: Sourced directly from Assumption FA-06; baseline operational benchmark of unassigned or delayed follow-up schedules identified in activity tracking logs (~14.0%).
A6: B-05 | B6: current_handling_effort_per_straightforward_case | C6: =Assumptions!C5 -> 18 | D6: minutes/case | E6: Operations leadership (FA-04) | F6: Medium | G6: Baseline handling time per straightforward case prior to automation (FA-04) | H6: Sourced directly from Assumption FA-04; operations leadership baseline time-and-motion figure for end-to-end handling of routine arrears inquiries (18 mins/case).
A7: B-06 | B7: monthly_straightforward_case_handling_effort_hours | C7: =ROUND((C3*C6)/60, 1) -> 369.9 | D7: hours/month | E7: Calculated from B-02 and B-05 | F7: Medium | G7: Total monthly staff handling effort devoted to straightforward delinquent cases (1,233 cases * 18 mins / 60) | H7: Calculated as =(B-02 * B-05) / 60; (1,233 straightforward monthly cases * 18 minutes handling time) / 60 minutes = 369.9 representative handling hours per month.
A8: B-07 | B8: monthly_admin_hours_lost_to_reconciliation | C8: =ROUND(C4*Assumptions!C3, 1) -> 69.5 | D8: hours/month | E8: Calculated from B-03 & Assumptions (FA-02) | F8: Medium | G8: Monthly administrative hours lost to manual reconciliation across 21 working days per month (FA-02) | H8: Calculated as =B-03 * FA-02; 3.31 daily admin reconciliation hours * 21 working days per month (FA-02) = 69.51 monthly representative hours lost to reconciliation.
A9: B-08 | B9: total_monthly_manual_effort_hours | C9: =ROUND(C7+C8, 1) -> 439.4 | D9: hours/month | E9: Calculated from B-06 and B-07 | F9: Medium | G9: Combined baseline monthly operational effort from handling straightforward cases and manual reconciliation | H9: Calculated as =B-06 + B-07; 369.9 case handling hours + 69.5 manual reconciliation hours = 439.4 total monthly hours of manual operational effort targeted for automation.

Sheet Opportunities
A1: opportunity_id | B1: opportunity_name | C1: description | D1: implementation_cost | E1: annual_hours_saved | F1: annual_cost_saved | G1: annual_revenue_uplift | H1: soft_benefit_note | I1: confidence_level | J1: priority_rank | K1: Calculation & Origin
A2: OP-01 | B2: self-serve balance and arrears view | C2: Enables customers to view current balances, arrears breakdown, and statement history online, deflecting routine inbound queries. | D2: =Assumptions!$C$11 -> 45000 | E2: =Assumptions!$C$25 -> 404 | F2: =E2*Assumptions!$C$2 -> 8888 | G2: 0 | H2: Empowers customers with transparent balance information, reducing call anxiety and inbound dispute volume. | I2: High | J2: 3 | K2: Implementation cost from FA-10 (£45k); Hours saved (404 hrs/yr) = (6,347 mins / 60 / 66 tracking days) * 252 working days/yr = 403.9 ≈ 404 hrs/yr (annualized from 1,400 status checks under FA-24); Cost saved = 404 hrs * £22/hr (FA-01) = £8,888. Lineage from notes SN-001, SN-065, SN-082.
A3: OP-02 | B3: contact detail confirmation or update request | C3: Allows customers to confirm and update their contact details online, preventing lost outreach and mail returns. | D3: =Assumptions!$C$11 -> 45000 | E3: 240 | F3: =E3*Assumptions!$C$2 -> 5280 | G3: 0 | H3: Maintains high digital contactability (99.7%) and reduces regulatory risk from outdated customer records. | I3: High | J3: 5 | K3: Implementation cost from FA-10 (£45k); Hours saved (240 hrs/yr) = 20 hrs/mo * 12 mos (~0.95 hrs/day across 252 working days, FA-21) avoiding manual address/phone verification; Cost saved = 240 hrs * £22/hr (FA-01) = £5,280. Lineage from contactability data (FA-14: 99.7%) and note SN-088.
A4: OP-03 | B4: digital promise-to-pay capture | C4: Captures digital payment promises and scheduled payment dates online without requiring live agent intervention. | D4: =Assumptions!$C$11 -> 45000 | E4: 360 | F4: =E4*Assumptions!$C$2 -> 7920 | G4: =Assumptions!$C$9*Assumptions!$C$10*12*Assumptions!$C$24 -> 912000 | H4: Secures prompt customer payment commitments and establishes clear behavioral accountability early in arrears. | I4: Medium | J4: 2 | K4: Implementation cost from FA-10 (£45k); Hours saved (360 hrs/yr) = 30 hrs/mo * 12 mos (~1.43 hrs/day across 252 working days) by deflecting routine payment promise calls; Cost saved = 360 hrs * £22/hr (FA-01) = £7,920; Revenue uplift = £8.0M baseline * 12 mos * 2.5% promise capture uplift * 38% straightforward case share (FA-08, FA-09, FA-23) = £912,000. Lineage: SN-112, SN-126.
A5: OP-04 | B5: eligible payment-plan selection | C5: Presents eligible self-service installment plans and payment schedules tailored to customer arrears balance. | D5: =Assumptions!$C$12 -> 85000 | E5: 986 | F5: =E5*Assumptions!$C$2 -> 21692 | G5: =Assumptions!$C$8*Assumptions!$C$10*12*Assumptions!$C$24 -> 1459200 | H5: Drives sustainable debt rehabilitation through manageable terms while preserving agent capacity for complex cases. | I5: Medium | J5: 1 | K5: Implementation cost from FA-11 (£85k); Hours saved (986 hrs/yr) = 1,233 straightforward cases/mo (B-02) * 8 mins saved/case (18 min baseline FA-04 - 10 min target FA-05) * 50% portal self-service adoption * 12 mos / 60 = 986.4 ≈ 986 hrs/yr; Cost saved = 986 hrs * £22/hr (FA-01) = £21,692; Revenue uplift = £8.0M baseline * 12 mos * 4.0% plan selection uplift * 38% straightforward case share (FA-07, FA-09, FA-23) = £1,459,200. Lineage: SN-001, SN-065.
A6: OP-05 | B6: rules-based routing to representatives | C6: Triages cases using predefined rules to direct routine accounts to self-service and route complex or vulnerable debt to specialists. | D6: =Assumptions!$C$12 -> 85000 | E6: 650 | F6: =E6*Assumptions!$C$2 -> 14300 | G6: 0 | H6: Unblocks frontline queues, accelerates straightforward resolution, and protects vulnerable debtors with specialist care. | I6: High | J6: 4 | K6: Implementation cost from FA-11 (£85k); Hours saved (650 hrs/yr) = ~54.2 hrs/mo (~2.58 hrs/day across 252 working days) from automated queue triage and deflection of straightforward cases (FA-03); Cost saved = 650 hrs * £22/hr (FA-01) = £14,300. Lineage from queue friction notes SN-003, SN-029, SN-039, SN-057, SN-079, SN-100.
A7: OP-06 | B7: portal interaction history for representatives | C7: Provides representatives with a unified log of customer portal actions, payment agreements, and communication history. | D7: =Assumptions!$C$11 -> 45000 | E7: ='Baseline metrics'!$C$8*12 -> 834 | F7: =E7*Assumptions!$C$2 -> 18348 | G7: 0 | H7: Eliminates monthly manual spreadsheet reconciliation, prevents duplicate outreach, and provides a clear audit trail. | I7: High | J7: 7 | K7: Implementation cost from FA-10 (£45k); Hours saved (834 hrs/yr) = 69.5 hrs/mo * 12 mos (from 3.31 hrs/day * 21 days/mo, B-03, B-07; eliminates 13,123 mins of reconciliation across 66 tracking days); Cost saved = 834 hrs * £22/hr (FA-01) = £18,348. Lineage: SN-008, SN-011, SN-025, SN-038, SN-123.
A8: OP-07 | B8: automated follow-up reminders | C8: Dispatches automated multi-channel SMS and email reminders for upcoming payment due dates, callbacks, and broken promises. | D8: =Assumptions!$C$11 -> 45000 | E8: 420 | F8: =E8*Assumptions!$C$2 -> 9240 | G8: 0 | H8: Directly addresses the 14% missed follow-up rate, prevents shift handoff drops, and improves promise-kept rates. | I8: Medium | J8: 6 | K8: Implementation cost from FA-10 (£45k); Hours saved (420 hrs/yr) = 35 hrs/mo * 12 mos (~1.67 hrs/day across 252 working days) from automating SMS/email notification workflows; Cost saved = 420 hrs * £22/hr (FA-01) = £9,240. Lineage: resolves 14% missed follow-up rate (FA-06, B-04) and 20% shift handoff loss (FA-20, SN-040, SN-105).

Sheet Calculations
A1: Opportunity ID | B1: Opportunity Name | C1: Implementation Cost | D1: Annual Cost Saved | E1: Annual Revenue Uplift | F1: Annual Total Benefit | G1: Net Benefit | H1: ROI Percentage | I1: Payback Months | J1: Calculation Formula
A2: =Opportunities!A2 -> OP-01 | B2: =Opportunities!B2 -> self-serve balance and arrears view | C2: =Opportunities!D2 -> 45000 | D2: =Opportunities!F2 -> 8888 | E2: =Opportunities!G2 -> 0 | F2: =D2+E2 -> 8888 | G2: =F2-C2 -> -36112 | H2: =IF(C2>0, G2/C2, 0) -> -0.80248889 | I2: =IF(F2>0, C2/(F2/12), "N/A") -> 60.756076 | J2: Total Benefit = Cost Saved + Revenue Uplift; Net Benefit = Total Benefit - Implementation Cost; ROI = Net Benefit / Implementation Cost; Payback = Implementation Cost / (Total Benefit / 12)
A3: =Opportunities!A3 -> OP-02 | B3: =Opportunities!B3 -> contact detail confirmation or update request | C3: =Opportunities!D3 -> 45000 | D3: =Opportunities!F3 -> 5280 | E3: =Opportunities!G3 -> 0 | F3: =D3+E3 -> 5280 | G3: =F3-C3 -> -39720 | H3: =IF(C3>0, G3/C3, 0) -> -0.88266667 | I3: =IF(F3>0, C3/(F3/12), "N/A") -> 102.27273 | J3: Total Benefit = Cost Saved + Revenue Uplift; Net Benefit = Total Benefit - Implementation Cost; ROI = Net Benefit / Implementation Cost; Payback = Implementation Cost / (Total Benefit / 12)
A4: =Opportunities!A4 -> OP-03 | B4: =Opportunities!B4 -> digital promise-to-pay capture | C4: =Opportunities!D4 -> 45000 | D4: =Opportunities!F4 -> 7920 | E4: =Opportunities!G4 -> 912000 | F4: =D4+E4 -> 919920 | G4: =F4-C4 -> 874920 | H4: =IF(C4>0, G4/C4, 0) -> 19.442667 | I4: =IF(F4>0, C4/(F4/12), "N/A") -> 0.58700757 | J4: Total Benefit = Cost Saved + Revenue Uplift; Net Benefit = Total Benefit - Implementation Cost; ROI = Net Benefit / Implementation Cost; Payback = Implementation Cost / (Total Benefit / 12)
A5: =Opportunities!A5 -> OP-04 | B5: =Opportunities!B5 -> eligible payment-plan selection | C5: =Opportunities!D5 -> 85000 | D5: =Opportunities!F5 -> 21692 | E5: =Opportunities!G5 -> 1459200 | F5: =D5+E5 -> 1480892 | G5: =F5-C5 -> 1395892 | H5: =IF(C5>0, G5/C5, 0) -> 16.422259 | I5: =IF(F5>0, C5/(F5/12), "N/A") -> 0.68877406 | J5: Total Benefit = Cost Saved + Revenue Uplift; Net Benefit = Total Benefit - Implementation Cost; ROI = Net Benefit / Implementation Cost; Payback = Implementation Cost / (Total Benefit / 12)
A6: =Opportunities!A6 -> OP-05 | B6: =Opportunities!B6 -> rules-based routing to representatives | C6: =Opportunities!D6 -> 85000 | D6: =Opportunities!F6 -> 14300 | E6: =Opportunities!G6 -> 0 | F6: =D6+E6 -> 14300 | G6: =F6-C6 -> -70700 | H6: =IF(C6>0, G6/C6, 0) -> -0.83176471 | I6: =IF(F6>0, C6/(F6/12), "N/A") -> 71.328671 | J6: Total Benefit = Cost Saved + Revenue Uplift; Net Benefit = Total Benefit - Implementation Cost; ROI = Net Benefit / Implementation Cost; Payback = Implementation Cost / (Total Benefit / 12)
A7: =Opportunities!A7 -> OP-06 | B7: =Opportunities!B7 -> portal interaction history for representatives | C7: =Opportunities!D7 -> 45000 | D7: =Opportunities!F7 -> 18348 | E7: =Opportunities!G7 -> 0 | F7: =D7+E7 -> 18348 | G7: =F7-C7 -> -26652 | H7: =IF(C7>0, G7/C7, 0) -> -0.59226667 | I7: =IF(F7>0, C7/(F7/12), "N/A") -> 29.431001 | J7: Total Benefit = Cost Saved + Revenue Uplift; Net Benefit = Total Benefit - Implementation Cost; ROI = Net Benefit / Implementation Cost; Payback = Implementation Cost / (Total Benefit / 12)
A8: =Opportunities!A8 -> OP-07 | B8: =Opportunities!B8 -> automated follow-up reminders | C8: =Opportunities!D8 -> 45000 | D8: =Opportunities!F8 -> 9240 | E8: =Opportunities!G8 -> 0 | F8: =D8+E8 -> 9240 | G8: =F8-C8 -> -35760 | H8: =IF(C8>0, G8/C8, 0) -> -0.79466667 | I8: =IF(F8>0, C8/(F8/12), "N/A") -> 58.441558 | J8: Total Benefit = Cost Saved + Revenue Uplift; Net Benefit = Total Benefit - Implementation Cost; ROI = Net Benefit / Implementation Cost; Payback = Implementation Cost / (Total Benefit / 12)
A9: Portfolio Total | B9: All Opportunities Rollup | C9: =SUM(C2:C8) -> 395000 | D9: =SUM(D2:D8) -> 85668 | E9: =SUM(E2:E8) -> 2371200 | F9: =SUM(F2:F8) -> 2456868 | G9: =SUM(G2:G8) -> 2061868 | H9: =IF(C9>0, G9/C9, 0) -> 5.219919 | I9: =IF(F9>0, C9/(F9/12), "N/A") -> 1.9292856 | J9: Portfolio totals and aggregate weighted metrics (Net Benefit = Total Benefit - Total Cost; Overall ROI = Net Benefit / Total Cost; Portfolio Payback = Total Cost / (Total Benefit / 12))

Sheet ROI Summary
A1: opportunity_id | B1: opportunity_name | C1: total_benefit | D1: net_benefit | E1: roi_percent | F1: payback_months | G1: effort_score | H1: confidence_level | I1: recommendation_note
A2: OP-01 | B2: =Calculations!B2 -> self-serve balance and arrears view | C2: =Calculations!F2 -> 8888 | D2: =Calculations!G2 -> -36112 | E2: =Calculations!H2 -> -0.80248889 | F2: =Calculations!I2 -> 60.756076 | G2: Low | H2: =Opportunities!I2 -> High | I2: Core Week 2 Scope: Foundational self-service balance & arrears view (JTBD-01); transparent debt visibility drives customer engagement.
A3: OP-02 | B3: =Calculations!B3 -> contact detail confirmation or update request | C3: =Calculations!F3 -> 5280 | D3: =Calculations!G3 -> -39720 | E3: =Calculations!H3 -> -0.88266667 | F3: =Calculations!I3 -> 102.27273 | G3: Low | H3: =Opportunities!I3 -> High | I3: Secondary / Fast-follow: Contact detail updates maintain 99.7% contactability and eliminate mail returns; low effort bundle for Week 2.
A4: OP-03 | B4: =Calculations!B4 -> digital promise-to-pay capture | C4: =Calculations!F4 -> 919920 | D4: =Calculations!G4 -> 874920 | E4: =Calculations!H4 -> 19.442667 | F4: =Calculations!I4 -> 0.58700757 | G4: Low | H4: =Opportunities!I4 -> Medium | I4: Essential Week 2 Scope: Top ROI quick win (£912k revenue uplift, 0.6 mo payback); captures digital payment promises early in delinquency.
A5: OP-04 | B5: =Calculations!B5 -> eligible payment-plan selection | C5: =Calculations!F5 -> 1480892 | D5: =Calculations!G5 -> 1395892 | E5: =Calculations!H5 -> 16.422259 | F5: =Calculations!I5 -> 0.68877406 | G5: Medium | H5: =Opportunities!I5 -> Medium | I5: Primary Week 2 Priority: Highest monetary return (£1.46M revenue uplift, £1.40M net benefit); self-service installment plan selection.
A6: OP-05 | B6: =Calculations!B6 -> rules-based routing to representatives | C6: =Calculations!F6 -> 14300 | D6: =Calculations!G6 -> -70700 | E6: =Calculations!H6 -> -0.83176471 | F6: =Calculations!I6 -> 71.328671 | G6: Medium | H6: =Opportunities!I6 -> High | I6: Essential Week 2 Scope: Operational backbone & triage safety shield (JTBD-04/10); routes routine cases to portal and vulnerable debt to specialists.
A7: OP-06 | B7: =Calculations!B7 -> portal interaction history for representatives | C7: =Calculations!F7 -> 18348 | D7: =Calculations!G7 -> -26652 | E7: =Calculations!H7 -> -0.59226667 | F7: =Calculations!I7 -> 29.431001 | G7: Low | H7: =Opportunities!I7 -> High | I7: Deferred Post-Week 2: Unifies staff portal interaction history (834 hrs saved); deploy after core debtor-facing portal features.
A8: OP-07 | B8: =Calculations!B8 -> automated follow-up reminders | C8: =Calculations!F8 -> 9240 | D8: =Calculations!G8 -> -35760 | E8: =Calculations!H8 -> -0.79466667 | F8: =Calculations!I8 -> 58.441558 | G8: Low | H8: =Opportunities!I8 -> Medium | I8: Sprint 2 Follow-on: Automated reminders targeting 14% missed follow-up rate; activate once digital promise workflows are live.
A9: Portfolio Total | B9: =Calculations!B9 -> All Opportunities Rollup | C9: =Calculations!F9 -> 2456868 | D9: =Calculations!G9 -> 2061868 | E9: =Calculations!H9 -> 5.219919 | F9: =Calculations!I9 -> 1.9292856 | G9: Blended (Total £395k) | H9: High / Medium | I9: Portfolio Recommendation: Prioritize OP-01, OP-03, OP-04, and OP-05 for Week 2 core scope to capture 97%+ of portfolio financial return.
A11: CONSERVATIVE SCENARIO (30% Lower Revenue Uplift, 20% Lower Operational Time Savings)
A12: opportunity_id | B12: opportunity_name | C12: total_benefit | D12: net_benefit | E12: roi_percent | F12: payback_months | G12: effort_score | H12: confidence_level | I12: scenario_note
